2025-05-29 23:42:45,318 [INFO] ipfs_datasets.mcp_server: Starting server at 127.0.0.1:8000
2025-05-29 23:42:45,324 [INFO] ipfs_datasets.mcp_server: Registered tool: save_dataset
2025-05-29 23:42:45,327 [INFO] ipfs_datasets.mcp_server: Registered tool: convert_dataset_format
2025-05-29 23:42:45,329 [INFO] ipfs_datasets.mcp_server: Registered tool: load_dataset
2025-05-29 23:42:45,331 [INFO] ipfs_datasets.mcp_server: Registered tool: ClaudesDatasetTool
2025-05-29 23:42:45,334 [INFO] ipfs_datasets.mcp_server: Registered tool: process_dataset
2025-05-29 23:42:45,337 [INFO] ipfs_datasets.mcp_server: Registered tool: get_from_ipfs
2025-05-29 23:42:45,340 [INFO] ipfs_datasets.mcp_server: Registered tool: pin_to_ipfs
2025-05-29 23:42:45,342 [INFO] ipfs_datasets.mcp_server: Registered tool: ClaudesIPFSTool
2025-05-29 23:42:45,346 [INFO] ipfs_datasets.mcp_server: Registered tool: get_global_manager
2025-05-29 23:42:45,348 [INFO] ipfs_datasets.mcp_server: Registered tool: reset_global_manager
2025-05-29 23:42:45,353 [INFO] ipfs_datasets.mcp_server: Registered tool: search_vector_index
2025-05-29 23:42:45,359 [INFO] ipfs_datasets.mcp_server: Registered tool: create_vector_index
2025-05-29 23:42:45,364 [INFO] ipfs_datasets.mcp_server: Registered tool: query_knowledge_graph
2025-05-29 23:42:45,384 [INFO] ipfs_datasets.mcp_server: Registered tool: AuditTool
2025-05-29 23:42:45,389 [INFO] ipfs_datasets.mcp_server: Registered tool: record_audit_event
2025-05-29 23:42:45,393 [INFO] ipfs_datasets.mcp_server: Registered tool: generate_audit_report
2025-05-29 23:42:45,431 [ERROR] ipfs_datasets.mcp_server: Error registering development tools: unindent does not match any outer indentation level (documentation_generator_broken.py, line 784)
2025-05-29 23:42:45,437 [INFO] ipfs_datasets.mcp_server: Registered tool: check_access_permission
2025-05-29 23:42:45,443 [INFO] ipfs_datasets.mcp_server: Registered tool: record_provenance
2025-05-29 23:42:45,445 [INFO] ipfs_datasets.mcp_server: Registered tool: ClaudesProvenanceTool
2025-05-29 23:42:45,446 [INFO] ipfs_datasets.mcp_server: Registered 19 tools with the MCP server
2025-05-29 23:42:45,453 [INFO] ipfs_kit_py: Auto-downloading IPFS binaries for Linux x86_64
/bin/sh: 1: /home/barberb/ipfs_datasets_py/.venv/lib/python3.12/site-packages/ipfs_kit_py/bin/ipfs: not found

Redirecting output to ‘wget-log.4’.
mv: cannot create regular file '/usr/local/bin/ipfs': Permission denied
mv: cannot move './ipfs' to '/usr/bin/ipfs': Permission denied
mv: cannot stat 'ipfs': No such file or directory
Command '/home/barberb/ipfs_datasets_py/.venv/lib/python3.12/site-packages/ipfs_kit_py/bin/ipfs' returned non-zero exit status 127.
2025-05-29 23:42:53,026 [WARNING] ipfs_kit_py: Failed to download IPFS daemon: Command 'cd /tmp/kubo && mkdir -p "/home/barberb/ipfs_datasets_py/.venv/lib/python3.12/site-packages/ipfs_kit_py/bin/" && mv ipfs "/home/barberb/ipfs_datasets_py/.venv/lib/python3.12/site-packages/ipfs_kit_py/bin/" && chmod +x "$/home/barberb/ipfs_datasets_py/.venv/lib/python3.12/site-packages/ipfs_kit_py/bin/ipfs"' returned non-zero exit status 1.
/bin/sh: 1: /home/barberb/ipfs_datasets_py/.venv/lib/python3.12/site-packages/ipfs_kit_py/bin/ipfs-cluster-follow: not found

Redirecting output to ‘wget-log.5’.
bash: install.sh: No such file or directory
Command '/home/barberb/ipfs_datasets_py/.venv/lib/python3.12/site-packages/ipfs_kit_py/bin/ipfs-cluster-follow' returned non-zero exit status 127.
2025-05-29 23:42:58,617 [WARNING] ipfs_kit_py: Failed to download IPFS cluster service: Command 'cd /tmp/ipfs-cluster-service && bash install.sh' returned non-zero exit status 127.
/bin/sh: 1: /home/barberb/ipfs_datasets_py/.venv/lib/python3.12/site-packages/ipfs_kit_py/bin/ipfs-cluster-ctl: not found

Redirecting output to ‘wget-log.6’.
bash: install.sh: No such file or directory
Command '/home/barberb/ipfs_datasets_py/.venv/lib/python3.12/site-packages/ipfs_kit_py/bin/ipfs-cluster-ctl' returned non-zero exit status 127.
2025-05-29 23:43:02,285 [WARNING] ipfs_kit_py: Failed to download IPFS cluster control: Command 'cd /tmp/ipfs-cluster-ctl && bash install.sh' returned non-zero exit status 127.
/bin/sh: 1: /home/barberb/ipfs_datasets_py/.venv/lib/python3.12/site-packages/ipfs_kit_py/bin/ipfs-cluster-follow: not found

Redirecting output to ‘wget-log.7’.
bash: install.sh: No such file or directory
Command '/home/barberb/ipfs_datasets_py/.venv/lib/python3.12/site-packages/ipfs_kit_py/bin/ipfs-cluster-follow' returned non-zero exit status 127.
2025-05-29 23:43:05,840 [WARNING] ipfs_kit_py: Failed to download IPFS cluster follow: Command 'cd /tmp/ipfs-cluster-follow && bash install.sh' returned non-zero exit status 127.
2025-05-29 23:43:05,841 [INFO] ipfs_kit_py: IPFS binary downloads completed
2025-05-29 23:43:06,576 [INFO] ipfs_kit_py.webrtc_streaming: OpenCV not found, some video processing features will be unavailable
2025-05-29 23:43:06,576 [INFO] ipfs_kit_py.webrtc_streaming: PyAV not found, media handling features will be unavailable
2025-05-29 23:43:06,577 [INFO] ipfs_kit_py.webrtc_streaming: aiortc not found, WebRTC features will be unavailable
2025-05-29 23:43:06,586 [INFO] ipfs_kit_py.webrtc_streaming: Notification system not available
2025-05-29 23:43:06,600 [ERROR] ipfs_datasets.mcp_server: Error starting server: FastMCP.run() got an unexpected keyword argument 'host'
Traceback (most recent call last):
  File "/home/barberb/ipfs_datasets_py/ipfs_datasets_py/mcp_server/server.py", line 330, in start_server
    asyncio.run(server.start(host, port))
  File "/usr/lib/python3.12/asyncio/runners.py", line 194, in run
    return runner.run(main)
           ^^^^^^^^^^^^^^^^
  File "/usr/lib/python3.12/asyncio/runners.py", line 118, in run
    return self._loop.run_until_complete(task)
           ^^^^^^^^^^^^^^^^^^^^^^^^^^^^^^^^^^^
  File "/usr/lib/python3.12/asyncio/base_events.py", line 687, in run_until_complete
    return future.result()
           ^^^^^^^^^^^^^^^
  File "/home/barberb/ipfs_datasets_py/ipfs_datasets_py/mcp_server/server.py", line 278, in start
    await self.mcp.run(host=host, port=port)
          ^^^^^^^^^^^^^^^^^^^^^^^^^^^^^^^^^^
TypeError: FastMCP.run() got an unexpected keyword argument 'host'
